Workbook

Sheet YouTube Main 📌
A1: Episode | B1: Data | C1: Title | D1: Status | E1: Collection | F1: Sound Effects | G1: Music | H1: Subtitles | I1: Tumbnaill
A2: NETCAT Mastery — From Zero to Security Researcher #6 | B2: 46299 | C2: {=_xlfn.XLOOKUP(_YouTube[Episode],'Contents 🖊️'!C:C,'Contents 🖊️'!E:E,"")} -> Netcat -n Flag = Faster Scans(Skip DNS) #6 | D2: Public | E2: {=_xlfn.XLOOKUP(_YouTube[Episode],'Contents 🖊️'!C:C,'Episodes ⏭️'!B:B,"")} -> NETCAT Mastery | F2: TRUE | G2: FALSE | H2: =Countif('Subtitles 🔍'!A:A,_YouTube[Episode]) -> 0 | I2: TRUE
A3: NETCAT Mastery — From Zero to Security Researcher #8 | B3: 46299 | C3: {=_xlfn.XLOOKUP(_YouTube[Episode],'Contents 🖊️'!C:C,'Contents 🖊️'!E:E,"")} -> Netcat Trick: Send a Message With One Line #8 | D3: Public | E3: {=_xlfn.XLOOKUP(_YouTube[Episode],'Contents 🖊️'!C:C,'Episodes ⏭️'!B:B,"")} -> NETCAT Mastery | F3: TRUE | G3: FALSE | H3: =Countif('Subtitles 🔍'!A:A,_YouTube[Episode]) -> 0 | I3: TRUE
A4: Logic in Motion #13 | B4: 46299 | C4: {=_xlfn.XLOOKUP(_YouTube[Episode],'Contents 🖊️'!C:C,'Contents 🖊️'!E:E,"")} -> What If the Constant Never Changes? | Logic in Motion #13 | D4: Public | E4: {=_xlfn.XLOOKUP(_YouTube[Episode],'Contents 🖊️'!C:C,'Episodes ⏭️'!B:B,"")} -> Logic in Motion | F4: FALSE | G4: TRUE | H4: =Countif('Subtitles 🔍'!A:A,_YouTube[Episode]) -> 0 | I4: TRUE
A5: Master Nmap Recon: Zero to Security Researcher#29 | B5: 46299 | C5: {=_xlfn.XLOOKUP(_YouTube[Episode],'Contents 🖊️'!C:C,'Contents 🖊️'!E:E,"")} -> Nmap Default Scripts(-sC) Explained 🔍 #29 | D5: Public | E5: {=_xlfn.XLOOKUP(_YouTube[Episode],'Contents 🖊️'!C:C,'Episodes ⏭️'!B:B,"")} -> Master Nmap | F5: TRUE | G5: FALSE | H5: =Countif('Subtitles 🔍'!A:A,_YouTube[Episode]) -> 0 | I5: TRUE
A6: Logic in Motion #14 | B6: 46300 | C6: {=_xlfn.XLOOKUP(_YouTube[Episode],'Contents 🖊️'!C:C,'Contents 🖊️'!E:E,"")} -> The Epitrochoid Lattice | D6: Private | E6: {=_xlfn.XLOOKUP(_YouTube[Episode],'Contents 🖊️'!C:C,'Episodes ⏭️'!B:B,"")} -> Logic in Motion | F6: FALSE | G6: TRUE | H6: =Countif('Subtitles 🔍'!A:A,_YouTube[Episode]) -> 0 | I6: FALSE
A7: Logic in Motion #15 | B7: 46300 | C7: {=_xlfn.XLOOKUP(_YouTube[Episode],'Contents 🖊️'!C:C,'Contents 🖊️'!E:E,"")} -> The Nephroid Web(Two-Cusp Epicycloid) | Logic in Motion #15 | D7: Private | E7: {=_xlfn.XLOOKUP(_YouTube[Episode],'Contents 🖊️'!C:C,'Episodes ⏭️'!B:B,"")} -> Logic in Motion | F7: FALSE | G7: TRUE | H7: =Countif('Subtitles 🔍'!A:A,_YouTube[Episode]) -> 0 | I7: FALSE
A8: Logic in Motion #16 | B8: 46300 | C8: {=_xlfn.XLOOKUP(_YouTube[Episode],'Contents 🖊️'!C:C,'Contents 🖊️'!E:E,"")} -> The Hypnotic Three Cusp Star | Logic in Motion #16 | D8: Private | E8: {=_xlfn.XLOOKUP(_YouTube[Episode],'Contents 🖊️'!C:C,'Episodes ⏭️'!B:B,"")} -> Logic in Motion | F8: FALSE | G8: TRUE | H8: =Countif('Subtitles 🔍'!A:A,_YouTube[Episode]) -> 0 | I8: FALSE
A9: Logic in Motion #14 | B9: 46301 | C9: {=_xlfn.XLOOKUP(_YouTube[Episode],'Contents 🖊️'!C:C,'Contents 🖊️'!E:E,"")} -> The Epitrochoid Lattice | D9: Public | E9: {=_xlfn.XLOOKUP(_YouTube[Episode],'Contents 🖊️'!C:C,'Episodes ⏭️'!B:B,"")} -> Logic in Motion | F9: FALSE | G9: TRUE | H9: =Countif('Subtitles 🔍'!A:A,_YouTube[Episode]) -> 0 | I9: TRUE
A10: Logic in Motion #15 | B10: 46300 | C10: {=_xlfn.XLOOKUP('YouTube Main 📌'!$A$2:$A$10,'Contents 🖊️'!C:C,'Contents 🖊️'!E:E,"")} -> The Nephroid Web(Two-Cusp Epicycloid) | Logic in Motion #15 | D10: Public | E10: {=_xlfn.XLOOKUP('YouTube Main 📌'!$A$2:$A$10,'Contents 🖊️'!C:C,'Episodes ⏭️'!B:B,"")} -> Logic in Motion | F10: FALSE | G10: TRUE | H10: =Countif('Subtitles 🔍'!A:A,_YouTube[Episode]) -> 0 | I10: FALSE
A11: Logic in Motion #16 | B11: 46300 | C11: {=_xlfn.XLOOKUP(_YouTube[Episode],'Contents 🖊️'!C:C,'Contents 🖊️'!E:E,"")} -> The Hypnotic Three Cusp Star | Logic in Motion #16 | D11: Public | E11: {=_xlfn.XLOOKUP(_YouTube[Episode],'Contents 🖊️'!C:C,'Episodes ⏭️'!B:B,"")} -> Logic in Motion | F11: FALSE | G11: TRUE | H11: =Countif('Subtitles 🔍'!A:A,_YouTube[Episode]) -> 0 | I11: FALSE
A12: NETCAT Mastery — From Zero to Security Researcher #20 | B12: 46302 | C12: {=_xlfn.XLOOKUP(_YouTube[Episode],'Contents 🖊️'!C:C,'Contents 🖊️'!E:E,"")} -> Netcat Fast Review | 19 Commands You Must Know #20 | D12: Private | E12: {=_xlfn.XLOOKUP(_YouTube[Episode],'Contents 🖊️'!C:C,'Episodes ⏭️'!B:B,"")} -> NETCAT Mastery | F12: TRUE | G12: FALSE | H12: =Countif('Subtitles 🔍'!A:A,_YouTube[Episode]) -> 0 | I12: TRUE
A13: Master Nmap Recon: Zero to Security Researcher#30 | B13: 46303 | C13: {=_xlfn.XLOOKUP(_YouTube[Episode],'Contents 🖊️'!C:C,'Contents 🖊️'!E:E,"")} -> OS Detection | D13: Private | E13: {=_xlfn.XLOOKUP(_YouTube[Episode],'Contents 🖊️'!C:C,'Episodes ⏭️'!B:B,"")} -> Master Nmap | F13: TRUE | G13: FALSE | H13: =Countif('Subtitles 🔍'!A:A,_YouTube[Episode]) -> 0 | I13: FALSE
A14: Logic in Motion #17 | B14: 46302 | C14: {=_xlfn.XLOOKUP(_YouTube[Episode],'Contents 🖊️'!C:C,'Contents 🖊️'!E:E,"")} -> The Lemniscate of Bernoulli | D14: Not List | E14: {=_xlfn.XLOOKUP(_YouTube[Episode],'Contents 🖊️'!C:C,'Episodes ⏭️'!B:B,"")} -> Logic in Motion | F14: TRUE | G14: FALSE | H14: =Countif('Subtitles 🔍'!A:A,_YouTube[Episode]) -> 0 | I14: FALSE

Sheet Contents 🖊️
A1: ROW | B1: ID | C1: Episode | D1: Language | E1: Title | F1: Description | G1: Tags | H1: Subtitles | I1: Related Video | J1: Pinned Comment | K1: Music | L1: Tumbnaill
A2: 1 | B2: ="CNT" & A2 -> CNT1 | C2: Master Nmap Recon: Zero to Security Researcher #DEMO | D2: English | E2: Master Nmap Recon | Collection DEMO | F2: Master Nmap Recon | Collection DEMO ⚡ DEMO of new Shorts series | one nmap switch per episode. Step by step until becoming a SECURITY researcher. Practice targets: LOCAL HOST(127.0.0.1) What you'll see in this teaser: 1. terminal: Kali-style recon vibe 2. Full aggressive scan typed at human pace: nmap -sS -sV -O -A -T4 --script=vuln 192.168.1.1 3. Realistic output: open ports, service versions, OS guess and NSE vuln hits AND WILL COVER IN THIS SERIES: Timing | Output | UDP | NSE | Exclude Note: This content is DEMO for new collection and NEXT Episode is the FIRST episode NEXT Episode: Episode 1: Host Discovery (-sn) Turn on notifications so you don't MISS new episodes! @Unique_Sources #Nmap #CyberSecurity #KaliLinux #PenetrationTesting #EthicalHacking #InfoSec #NetworkScanning #YouTubeShorts #ComingSoon #SecurityResearcher #Hacking #Recon #PortScan #Linux #TechEducation #LearnHacking #NmapTutorial
B3: ="CNT" & A3 -> CNT | C3: Master Nmap Recon: Zero to Security Researcher #0 | D3: English | E3: Start PENETRATION test | learning basics LINUX commands #00 | F3: Learn the 56 essential Linux commands you should master before running your first Nmap scan. Whether you're getting started with network security, ethical hacking, or Linux system administration, these foundational terminal commands will help you navigate, manage, and analyze your environment with confidence. 📌 Series: Master Nmap Recon 🔔 Subscribe for more quick networking and terminal tutorials! #Linux #Nmap #Cybersecurity #Networking #Terminal #SysAdmin #Shorts
B4: ="CNT" & A4 -> CNT | C4: Master Nmap Recon: Zero to Security Researcher#1 | D4: English | E4: First Nmap Command You Should Run | Check Version #01 | F4: Before you scan a single host check nmap version. Command: nmap --version That one line answers: 1. Is nmap installed? 2. Which version am I running? 3. Am I ready to start the lab? Habit: always confirm the tool exists before scanning. Next episode: Your First Nmap Scan → nmap localhost Practice: localhost(127.0.0.1) ⚠️ Lab ethics: only scan targets you own or have explicit permission to test. Collection: Master Nmap Recon: one nmap lesson per Short @Unique_Sources #Nmap #CyberSecurity #KaliLinux #EthicalHacking #InfoSec #Linux #Terminal #PenetrationTesting #Recon #YouTubeShorts #SecurityResearcher #NmapTutorial #CommandLine #LearnHacking
B5: ="CNT" & A5 -> CNT | C5: Master Nmap Recon: Zero to Security Researcher#2 | D5: English | E5: Your First Nmap Scan Should Be localhost Not a Random #02 | F5: When learning network scanning with Nmap NEVER scan random IP addresses or unauthorized networks. Always practice on localhost (127.0.0.1) or your own local test environment first! Command: nmap localhost Result: This scan will scan you machine local network. Next Episode: can One IP Address on Purpose 🔔 Subscribe @Unique_Sources #Nmap #CyberSecurity #Networking #EthicalHacking #TechShorts #LearnToCode
B6: ="CNT" & A6 -> CNT | C6: Master Nmap Recon: Zero to Security Researcher#3 | D6: English | E6: nmap 127.0.0.1 — Scan One IP Address on Purpose | Ep.03 | F6: Command: nmap 127.0.0.1 Why this matters: • One IP = one host in scope • No ambiguity about which address you're scanning • Same default TCP scan — focused target syntax Next: Scan by Hostname → when nmap resolves a name for you. ⚠️ Lab only: 127.0.0.1 / localhost / authorized targets. Subscribe @Unique_Sources — NMAP Mastery path. #Nmap #CyberSecurity #127001 #PortScan #EthicalHacking #KaliLinux
B7: ="CNT" & A7 -> CNT | C7: Master Nmap Recon: Zero to Security Researcher#4 | D7: English | E7: nmap localhost as a Hostname Target — Name Resolves to IP | Ep.04 | F7: Ep.03 typed the IP. Ep.04 types the hostname. Command: nmap localhost Lesson: nmap resolves the name first — your report shows `localhost (127.0.0.1)`. Same lab host. New skill: hostname targeting + reading resolution in output. Next: Scan Multiple Hosts in one command. #Nmap #CyberSecurity #DNS #Localhost #EthicalHacking
B8: ="CNT" & A8 -> CNT | C8: Master Nmap Recon: Zero to Security Researcher#5 | D8: English | E8: nmap 127.0.0.1 localhost — Scan Multiple Hosts in One Command | Ep.05 | F8: One target per scan? Not always. Ep.05: pass multiple hosts on one line. $ nmap 127.0.0.1 localhost Nmap runs a report for each target — watch the done line count hosts. Next: IP range syntax with hyphens. #Nmap #CyberSecurity #PortScan #EthicalHacking
B9: ="CNT" & A9 -> CNT | C9: Master Nmap Recon: Zero to Security Researcher#6 | D9: English | E9: nmap 127.0.0.1-1 — IP Range Syntax with Hyphens | Ep.06 | F9: Ep.06 introduces hyphen range syntax on a safe tiny scope. $ nmap 127.0.0.1-1 The `-1` expands the last octet — here it's just 127.0.0.1, but the habit scales. Always keep ranges authorized and small in the lab. Next: CIDR notation with /32. #Nmap #CyberSecurity #CIDR #PortScan #EthicalHacking
B10: ="CNT" & A10 -> CNT | C10: Master Nmap Recon: Zero to Security Researcher#7 | D10: English | E10: nmap -sn 127.0.0.1/32 — CIDR Notation as Your Target | Ep.07 | F10: Ep.07: express scope with CIDR. $ nmap -sn 127.0.0.1/32 -sn = host discovery only (no port table). /32 = one address — perfect safe loopback practice. Next: load targets from a file with -iL. #Nmap #CyberSecurity #CIDR #HostDiscovery #EthicalHacking
B11: ="CNT" & A11 -> CNT | C11: Master Nmap Recon: Zero to Security Researcher#8 | D11: English | E11: nmap -iL targets.txt — Load Targets from a File | Ep.08 | F11: Ep.08: feed nmap an inventory file. $ nmap -iL targets.txt -iL = input list — one host per line. Scales recon beyond typing IPs by hand. Next: preview scope with -sL (list scan). #Nmap #CyberSecurity #Recon #EthicalHacking #NetworkSecurity
B12: ="CNT" & A12 -> CNT | C12: Master Nmap Recon: Zero to Security Researcher#9 | D12: English | E12: nmap -sL 127.0.0.1/32 — List Scan: Preview Without Probing | Ep.09 | F12: Ep.09: preview scope before you scan. $ nmap -sL 127.0.0.1/32 -sL = list scan — enumerate targets with no probe packets. "0 hosts up" is normal — nothing was probed. Next: host discovery with -sn. #Nmap #CyberSecurity #Recon #EthicalHacking #NetworkSecurity
B13: ="CNT" & A13 -> CNT | C13: Master Nmap Recon: Zero to Security Researcher#10 | D13: English | E13: nmap -sn 127.0.0.1 — Host Discovery Without a Port Scan | Ep.10 | F13: Ep.10: find live hosts — skip the port table. $ nmap -sn 127.0.0.1 -sn = ping scan / host discovery only. No PORT STATE SERVICE — just aliveness. Next: speed it up by skipping DNS with -n. #Nmap #CyberSecurity #HostDiscovery #Recon #EthicalHacking
B14: ="CNT" & A14 -> CNT | C14: Master Nmap Recon: Zero to Security Researcher#11 | D14: English | E14: nmap -n — Skip DNS for Faster Scans | Ep.11 | F14: DNS slowing you down? Add -n. $ nmap -n -sn 127.0.0.1 -n skips reverse DNS — faster scans, less noise. Next: Assume Online with -Pn. Lab: 127.0.0.1 / localhost / scanme.nmap.org only. @Unique_Sources #Nmap #CyberSecurity #KaliLinux #EthicalHacking #InfoSec #YouTubeShorts
... B31: ="CNT" & A31 -> CNT | C31: Master Nmap Recon: Zero to Security Researcher#28 | D31: English | E31: How Hackers Fingerprint OPEN Services Version? | Master Nmap #28 | F31: You ran a port scan and discovered an open port, what’s your next move? To think like a cybersecurity researcher and ethical hacker, the critical next step is service fingerprinting and version detection. Knowing the exact software version running on an open port helps you identify known vulnerabilities, misconfigurations and outdated software. In this tutorial, we focus on identifying the OpenSSH service running on Port 22 using Nmap’s -sV switch. 💻 Command Used: $ nmap -sV -p 22 127.0.0.1 🔍 Flag Breakdown: -s: Service probe -V: Version detection -sV: Directs Nmap to interrogate open ports to determine the exact service/version info. -p 22: Restricts the scan specifically to Port 22 (SSH). 127.0.0.1: Scans the local loopback address (our isolated lab environment). ⚠️ Important Disclaimer: Educational Purposes Only: This video is created strictly for learning and authorized testing. Real ethical hackers and security researchers work to secure systems, share knowledge and protect the community. Authorized Testing Only: All demonstrations are performed in a controlled local lab environment (localhost). Never run port or vulnerability scans against networks, systems, or targets without explicit, written permission. 📌 Check the Pinned Comment: Why is precise version detection so important during an assessment? Let’s discuss below! ▶️ Next Up: Running Nmap Default Scripts with the -sC flag. Don't forget to subscribe so you don't miss the next episode! #Nmap #EthicalHacking #CyberSecurity #NetworkSecurity #InfoSec
B32: ="CNT" & A32 -> CNT | C32: Master Nmap Recon: Zero to Security Researcher#29 | D32: English | E32: Nmap Default Scripts(-sC) Explained 🔍 #29 | F32: You ran a port scan & discovered an open port, what’s your next move? If you tuned in last time, you know we used -sV to find out what software is running on Port 22. But knowing the version is only half the battle, to think like a cybersecurity researcher, the critical next step is automated vulnerability discovery. In this tutorial, we move beyond just identifying the service and start interrogating it using Nmap’s Default Scripts, also known as the -sC flag. 💻 Command Used: $ nmap -sC -p 22 127.0.0.1 🔍 Flag Breakdown: -sC: This is the star of the show. It directs Nmap to run a set of default scripts against the target port. The "C" stands for Category: These scripts are categorized as "default" & "safe" meaning they provide valuable reconnaissance without crashing the service. What it does: It probes for things like SSH host keys, supported authentication methods & potential misconfigurations. -p 22: Restricts the scan specifically to Port 22(SSH). 127.0.0.1: Scans the local loopback address(our isolated lab environment). ⚠️ Important Disclaimer: Educational Purposes Only. This video is strictly for learning & authorized testing. Real ethical hackers work to secure systems. Authorized Testing Only: All demonstrations are performed in a controlled local lab environment. Never run scans against targets without explicit written permission. 📌 Check the Pinned Comment: What is the difference between -sV & -sC? Let’s discuss below! ▶️ Next Up: We will combine everything we've learned so far. Don't forget to subscribe so you don't miss the next episode! #Nmap #EthicalHacking #CyberSecurity #NetworkSecurity #InfoSec #Shorts #PenTesting #SSH #NSE #NmapScripts | G32: nmap, nmap default scripts, nmap -sC, nmap scripts, NSE, nmap scripting engine, nmap tutorial, nmap for beginners, ethical hacking, cybersecurity, network security, infosec, penetration testing, port scanning, service fingerprinting, version detection, vulnerability scanning, ssh enumeration, nmap ssh, nmap commands, nmap basics, kali linux, reconnaissance, open port, cyber security tutorial, hacking tutorial, learn nmap, nmap shorts, cybersecurity shorts, ethical hacking shorts, nmap port 22, localhost scanning, authorized testing
B33: ="CNT" & A33 -> CNT | C33: Master Nmap Recon: Zero to Security Researcher#30 | D33: English | E33: OS Detection
B34: ="CNT" & A34 -> CNT | C34: Master Nmap Recon: Zero to Security Researcher#31 | D34: English | E34: Aggressive(-A)
B35: ="CNT" & A35 -> CNT | C35: Master Nmap Recon: Zero to Security Researcher#32 | D35: English | E35: UDP Scan(-sU)
B36: ="CNT" & A36 -> CNT | C36: Master Nmap Recon: Zero to Security Researcher#33 | D36: English | E36: ACK Scan(-sA)
B37: ="CNT" & A37 -> CNT | C37: Master Nmap Recon: Zero to Security Researcher#34 | D37: English | E37: FIN Scan(-sF)
B38: ="CNT" & A38 -> CNT | C38: Master Nmap Recon: Zero to Security Researcher#35 | D38: English | E38: FIN Scan(-sF)
B39: ="CNT" & A39 -> CNT | C39: Master Nmap Recon: Zero to Security Researcher#36 | D39: English | E39: FIN Scan(-sF)
B40: ="CNT" & A40 -> CNT | C40: Master Nmap Recon: Zero to Security Researcher#37 | D40: English | E40: Reason(--reason)
B41: ="CNT" & A41 -> CNT | C41: Master Nmap Recon: Zero to Security Researcher#38 | D41: English | E41: Greppable(-oG)
B42: ="CNT" & A42 -> CNT | C42: Master Nmap Recon: Zero to Security Researcher#39 | D42: English | E42: Traceroute
B43: ="CNT" & A43 -> CNT | C43: Master Nmap Recon: Zero to Security Researcher#40 | D43: English | E43: Banner Script
B44: ="CNT" & A44 -> CNT | C44: Logic in Motion #1 | D44: English | E44: How a Rolling Circle Draws Infinite Geometry | Logic in Motion #01 | F44: Visualizing mathematical beauty through code. In this episode of Logic in Motion, we explore Neon Orbit; a six-fold Spirograph mandala using hypothyroid curves. 📐 The Math & Logic: • Concept: Parametric rolling-circle curves • Key Formula / Rule: x = (R − r)·cos(t) + d·cos(((R − r) / r)·t) • Tools: Python / Turtle 🔁 Logic in Motion Series: • Watch the full playlist: https://youtube.com/playlist?list=PLMG4RCtlrh18&si=jl8Cz_FDYUVfpHno • Previous Episode: this is the first episode • Next Episode: Watch Angles Weave a Star | Logic in Motion #02 💻 Source Code & Resources: • Code repository / Gist: https://github.com/irAbs174/Logic_in_motion #LogicInMotion #CreativeCoding #Python #GenerativeArt #MathArt #Short
B45: ="CNT" & A45 -> CNT | C45: Logic in Motion #2 | D45: English | E45: Watch Angles Weave a Star | Logic in Motion #02 | F45: Visualizing mathematical beauty through code. In this episode of Logic in Motion we explore The Birth of a Star; intersecting polygons using star polygons. 📐 The Math & Logic: • Concept: Regular star polygons • Key Formula / Rule: step angle = 360° / points × 2 • Tools: JavaScript / Canvas 🔁 Logic in Motion Series: • Watch the full playlist: https://youtube.com/playlist?list=PLMG4RCtlrh18&si=jl8Cz_FDYUVfpHno • Previous Episode: How a Rolling Circle Draws Infinite Geometry | Logic in Motion #01 • Next Episode: The Secret Equation Behind a Seashell | Logic in Motion #03 💻 Source Code & Resources: • Code repository / Gist: https://github.com/irAbs174/Logic_in_motion #LogicInMotion #CreativeCoding #Python #GenerativeArt #MathArt #Short
B46: ="CNT" & A46 -> CNT | C46: Logic in Motion #3 | D46: English | E46: The Secret Equation Behind a Seashell | Logic in Motion #03 | F46: Visualizing mathematical beauty through code. In this episode of Logic in Motion we explore The Infinite Spiral; a golden-ratio seashell using a multi-harmonic logarithmic spiral. 📐 The Math & Logic: • Concept: Golden-ratio growth • Key Formula / Rule: r = growth · φ^(θ·0.28), φ ≈ 1.618 • Tools: JavaScript / Canvas 🔁 Logic in Motion Series: • Watch the full playlist: https://youtube.com/playlist?list=PLMG4RCtlrh18&si=jl8Cz_FDYUVfpHno • Previous Episode: Watch Angles Weave a Star | Logic in Motion #02 • Next Episode: The Secret Formula Behind the Quantum Rose #4 💻 Source Code & Resources: • Code repository / Gist: https://github.com/irAbs174/Logic_in_motion #LogicInMotion #CreativeCoding #javascript #GenerativeArt #MathArt #Short
B47: ="CNT" & A47 -> CNT | C47: Logic in Motion #4 | D47: English | E47: How One Cosine Draws a Rose | Logic in Motion #04 | F47: Drawing a Mathematical Quantum Rose Is Not Hard! In this episode of Logic in Motion, we explore The Quantum Rose & rhodonea harmonics, using a ROSE CURVE. 📐 The Math & Logic: • Concept: Polar rose curves • Key Formula / Rule: r = scale · cos(k·θ) • Tools: JavaScript / Canvas 🔁 Logic in Motion Series: • Watch the full playlist: https://youtube.com/playlist?list=PLMG4RCtlrh18&si=jl8Cz_FDYUVfpHno • Previous Episode: The Secret Equation Behind a Seashell | Logic in Motion #03 • Next Episode: The Koch Snowflake Algorithm | Logic in Motion #05 💻 Source Code & Resources: • Code repository / Gist: https://github.com/irAbs174/Logic_in_motion #LogicInMotion #CreativeCoding #Python #GenerativeArt #MathArt #Short
B48: ="CNT" & A48 -> CNT | C48: Logic in Motion #5 | D48: English | E48: 3 Lines of Code Created This INSANE Math Pattern | Lissajous Matrix #05 | F48: Welcome to Episode 5 of our series, where we dive into the fascinating world of harmonic interference with the Lissajous Matrix! In this episode, we'll explore how mathematical equations can create mesmerizing visual patterns using sinusoidal functions. Adjust the frequencies of X and Y to see how different combinations form unique Lissajous curves, revealing the beautiful interplay of mathematics and art. 🔍 Get hands-on with our simulator and experiment with parameters to discover these captivating shapes for yourself. Plus, check out our GitHub repository for the full code and dive deeper into the math behind the magic. Ready to explore the wonders of harmonic interference? Let’s get started! #LissajousMatrix #MathMagic #HarmonicInterference
B49: ="CNT" & A49 -> CNT | C49: Logic in Motion #6 | D49: English | E49: I coded a Hypnotic Math Simulator | Loginc In Motion #06 | F49: Ever wondered how math equations can draw hypnotizing neon patterns? In Episode 6 of the Math Simulator series, we dive into Hypotrochoid formulas (the math behind classic Spirographs) using JavaScript math functions cos() and sin() to render a dynamic "Neon Lattice" web in real-time. Adjusting parameters like Fixed Radius ($R$) and Rolling Radius ($r$) completely transforms the geometry! 👇 Drop a comment: What math concept should I visualize in Episode 7? #mathart #JavaScript #CreativeCoding #CodingTips #Hypotrochoid #VisualMath #WebDev #Shorts
B50: ="CNT" & A50 -> CNT | C50: Logic in Motion #7 | D50: English | E50: How 2 Lines of Code Create Nature’s Patterns 🌀 #07 | F50: Ever wondered how sunflowers arrange their seeds so perfectly? 🌀 It's all based on Fermat’s Spiral(Parabolic Phyllotaxis)! We can render this beautiful organic pattern in code. equations: let theta = i * 137.5 * (Math.PI / 180); let r = c * Math.sqrt(i); 🔔 Subscribe: @Unique_Sources #Coding #GenerativeArt #JavaScript #MathInCode #GoldenRatio #CreativeCoding #AlgorithmicArt #UniqueSources #DevLife #STEM #WebDev
B51: ="CNT" & A51 -> CNT | C51: Logic in Motion #8 | D51: English | E51: This Shape Comes From Just ONE Equation | Logic in Motion #08 | F51: What happens when mathematics turns into motion? This is the Astroid Curve(Hypocycloid with Four Cusps) and generated from the simple. 📐 The Math & Logic: • Concept: Complex quadratic iteration • Key Formula / Rule: x = a · cos³(t); y = a · sin³(t) • Tools: JavaScript / Canvas 🎬 Logic in Motion Series: • Watch the full playlist: https://youtube.com/playlist?list=PLMG4RCtlrh18&si=jl8Cz_FDYUVfpHno • Previous Episode: How 2 Lines of Code Create Nature's Patterns #07 • Next Episode: How a Circle Rolls Into a Heart | Logic in Motion #09 💻 Source Code & Resources: • Code repository / Gist: https://github.com/irAbs174/Logic_in_motion 🔔 @Unique_Sources #Shorts #Math #Mathematics #Astroid #Hypocycloid #Geometry #Coding #CreativeCoding #GenerativeArt #MathArt
B52: ="CNT" & A52 -> CNT | C52: Logic in Motion #9 | D52: English | E52: How a Circle Rolls Into a Heart | Logic in Motion #09 | F52: Visualizing mathematical beauty through code. In this episode of Logic in Motion, we explore The Cardioid Bloom; an epicycloid heart using a cardio-id. 📐 The Math & Logic: • Concept: Epicycloid with one cusp • Key Formula / Rule: r = a·(1 − cos(θ)) • Tools: JavaScript / Canvas 🔁 Logic in Motion Series: • Watch the full playlist: https://youtube.com/playlist?list=PLMG4RCtlrh18&si=jl8Cz_FDYUVfpHno • Previous Episode: This Shape Comes From Just ONE Equation | Astroid Curve #08 • Next Episode: Watch a Knot Live on a Donut | Logic in Motion #10 💻 Source Code & Resources: • Code repository / Gist: https://github.com/irAbs174/Logic_in_motion #generativeart #mathart #javascript #creativecoding #vanillajs #LogicInMotion
B53: ="CNT" & A53 -> CNT | C53: Logic in Motion #10 | D53: English | E53: How Code Draws a 3D Torus Knot #10 | F53: Watch how mathematical equations and code bring a hypnotic 3D Torus Knot to life Pure geometry in motion! Coded with parametric equations exploring 3D knot theory and computational geometry. Equations: r = R + r₀ cos(qφ), then x = r cos(pφ) How to recreate it: pick coprime winds p and q (classic pair: p = 2, q = 3), sample φ and project the tube onto the screen. Next Episode: The Lorenz At-tractor Logic In Motion Created by: @Unique_Sources #MathArt #CreativeCoding #Geometry #Python #3DArt #Shorts
B54: ="CNT" & A54 -> CNT | C54: Logic in Motion #11 | D54: English | E54: How 3 Lines of Math Draw Endless Chaos | Logic in Motion #11 | F54: Visualizing mathematical beauty through code. In this episode of Logic in Motion, we explore The Lorenz Attractor, a chaotic butterfly, using the Lorenz system. 📐 The Math & Logic: • Concept: Deterministic chaos • Key Formula / Rule: dx = σ(y − x)dt, dy = (x(ρ − z) − y)dt, dz = (xy − βz)dt • Tools: JavaScript / Canvas 🔁 Logic in Motion Series: • Watch the full playlist: https://youtube.com/playlist?list=PLMG4RCtlrh18&si=jl8Cz_FDYUVfpHno • Previous Episode: How Code Draws a 3D Torus Knot #10 • Next Episode: Why This Boundary Never Ends | Logic in Motion #12 #LogicInMotion #CreativeCoding #Python #GenerativeArt #MathArt #Short | I54: 1
B55: ="CNT" & A55 -> CNT | C55: Logic in Motion #12 | D55: English | E55: Why This Boundary Never Ends | Logic in Motion #12 | F55: Visualizing mathematical beauty through code. In this episode of Logic in Motion, we explore The Mandelbrot Fractal, infinite complex boundaries, using the Mandelbrot set. 📐 The Math & Logic: • Concept: Complex quadratic iteration • Key Formula / Rule: z → z² + c, colored by escape time • Tools: JavaScript / Canvas 🔁 Logic in Motion Series: • Watch the full playlist: https://youtube.com/playlist?list=PLMG4RCtlrh18&si=jl8Cz_FDYUVfpHno • Previous Episode: How 3 Lines of Math Draw Endless Chaos | Logic in Motion #11 • Next Episode: What If the Constant Never Changes | Logic in Motion #13 💻 Source Code & Resources: • Code repository / Gist: https://github.com/irAbs174/Logic_in_motion #LogicInMotion #CreativeCoding #Python #GenerativeArt #MathArt #Short
B56: ="CNT" & A56 -> CNT | C56: Logic in Motion #13 | D56: English | E56: What If the Constant Never Changes? | Logic in Motion #13 | F56: Visualizing mathematical beauty through code. In this episode of Logic in Motion, we explore The Julia Set, a fractal world where a single complex constant creates infinitely intricate boundaries. 📐 The Math & Logic: • Concept: Complex quadratic iteration • Key Formula / Rule: z = z² + c • Iteration: zx = zx² - zy² + cr • zy = 2 * zx_old * zy + ci • Tools: JavaScript / Canvas 🎬 Logic in Motion Series: • Watch the full playlist: https://www.youtube.com/playlist?list=PLMG4RCtlrh18 • Previous Episode: Why This Boundary Never Ends | Logic in Motion #12 • Next Episode: The Epitrochoid Lattice #14 💻 Source Code & Resources: • Code repository / Gist: https://github.com/irAbs174/Logic_in_motion #LogicInMotion #CreativeCoding #JavaScript #MathArt #Short | G56: Julia Set, Julia Set fractal, fractals, fractal art, creative coding, generative art, mathematical art, math art, complex numbers, complex plane, Mandelbrot, JavaScript, JavaScript canvas, coding art, generative design, algorithmic art, Logic in Motion, programming, mathematics, infinite patterns, #Shorts | I56: Why This Boundary Never Ends | Logic in Motion #12 | J56: 📌 One Constant, Infinite Complexity. The Julia Set is one of those rare places where math & art truly become inseparable. One constant c, one simple rule z = z² + c and infinite universe unfolds. 🔍 Try it yourself: Change the value of c just slightly & watch the entire fractal transform. Some values create connected "lightning" shapes, others shatter into dust. That boundary between order & chaos is what makes Julia Sets so fascinating. 🗨️ Question for you: What should we visualize next in Logic in Motion? Drop your ideas below! 👇 🔗 Links: • Full playlist: https://www.youtube.com/playlist?list=PLMG4RCtlrh18 • Source code: https://github.com/irAbs174/Logic_in_motion 🔔 LIKE & SUBSCRIBE helps more people discover the series. See you in the next episode! #LogicInMotion #JavaScript #MathArt
...

Sheet Episodes ⏭️
A1: Episode number | B1: Collection | C1: Episode | D1: Shared Link | E1: SCN Count
A2: DEMO | B2: Master Nmap | C2: =B2 & " #" &A2 -> Master Nmap #DEMO | D2: https://youtube.com/shorts/Wr0LckTDOgk?feature=share | E2: =COUNTIF('Scenses 🎬'!C:C,C2) -> 1
A3: 0 | B3: Master Nmap | C3: =B3 & " #" &A3 -> Master Nmap #0 | D3: https://youtube.com/shorts/AHJc3pj2LVE?feature=share | E3: =COUNTIF('Scenses 🎬'!C:C,C3) -> 0
A4: 1 | B4: Master Nmap | C4: =B4 & " #" &A4 -> Master Nmap #1 | D4: https://youtube.com/shorts/CwWa9-SD-48?feature=share | E4: =COUNTIF('Scenses 🎬'!C:C,C4) -> 0
A5: 2 | B5: Master Nmap | C5: =B5 & " #" &A5 -> Master Nmap #2 | D5: https://youtube.com/shorts/jnbl6Kq9YNI?feature=share | E5: =COUNTIF('Scenses 🎬'!C:C,C5) -> 0
A6: 3 | B6: Master Nmap | C6: =B6 & " #" &A6 -> Master Nmap #3 | D6: https://youtube.com/shorts/dxAxpfX1gp0?feature=share | E6: =COUNTIF('Scenses 🎬'!C:C,C6) -> 0
A7: 4 | B7: Master Nmap | C7: =B7 & " #" &A7 -> Master Nmap #4 | D7: https://youtube.com/shorts/bQ0B-3QwNak?feature=share | E7: =COUNTIF('Scenses 🎬'!C:C,C7) -> 0
A8: 5 | B8: Master Nmap | C8: =B8 & " #" &A8 -> Master Nmap #5 | D8: https://youtube.com/shorts/fO8g28j7oEM?feature=share | E8: =COUNTIF('Scenses 🎬'!C:C,C8) -> 0
A9: 6 | B9: Master Nmap | C9: =B9 & " #" &A9 -> Master Nmap #6 | D9: https://youtube.com/shorts/g3MrP-UlaWM?feature=share | E9: =COUNTIF('Scenses 🎬'!C:C,C9) -> 0
A10: 7 | B10: Master Nmap | C10: =B10 & " #" &A10 -> Master Nmap #7 | D10: https://youtube.com/shorts/0p9wD4eE54k?feature=share | E10: =COUNTIF('Scenses 🎬'!C:C,C10) -> 0
A11: 8 | B11: Master Nmap | C11: =B11 & " #" &A11 -> Master Nmap #8 | D11: https://youtube.com/shorts/NQt1ijYlImg?feature=share | E11: =COUNTIF('Scenses 🎬'!C:C,C11) -> 0
A12: 9 | B12: Master Nmap | C12: =B12 & " #" &A12 -> Master Nmap #9 | D12: https://youtube.com/shorts/ZQmcytmHKaE?feature=share | E12: =COUNTIF('Scenses 🎬'!C:C,C12) -> 0
A13: 10 | B13: Master Nmap | C13: =B13 & " #" &A13 -> Master Nmap #10 | D13: https://youtube.com/shorts/tLZR08RCPdo?feature=share | E13: =COUNTIF('Scenses 🎬'!C:C,C13) -> 0
A14: 11 | B14: Master Nmap | C14: =B14 & " #" &A14 -> Master Nmap #11 | D14: https://youtube.com/shorts/XOfsIh0-NUg?feature=share | E14: =COUNTIF('Scenses 🎬'!C:C,C14) -> 0
... A32: 29 | B32: Master Nmap | C32: =B32 & " #" &A32 -> Master Nmap #29 | D32: https://youtube.com/shorts/CY0aCY856xI?feature=share | E32: =COUNTIF('Scenses 🎬'!C:C,C32) -> 0
A33: 30 | B33: Master Nmap | C33: =B33 & " #" &A33 -> Master Nmap #30 | E33: =COUNTIF('Scenses 🎬'!C:C,C33) -> 0
A34: 31 | B34: Master Nmap | C34: =B34 & " #" &A34 -> Master Nmap #31 | E34: =COUNTIF('Scenses 🎬'!C:C,C34) -> 0
A35: 32 | B35: Master Nmap | C35: =B35 & " #" &A35 -> Master Nmap #32 | E35: =COUNTIF('Scenses 🎬'!C:C,C35) -> 0
A36: 33 | B36: Master Nmap | C36: =B36 & " #" &A36 -> Master Nmap #33 | E36: =COUNTIF('Scenses 🎬'!C:C,C36) -> 0
A37: 34 | B37: Master Nmap | C37: =B37 & " #" &A37 -> Master Nmap #34 | E37: =COUNTIF('Scenses 🎬'!C:C,C37) -> 0
A38: 35 | B38: Master Nmap | C38: =B38 & " #" &A38 -> Master Nmap #35 | E38: =COUNTIF('Scenses 🎬'!C:C,C38) -> 0
A39: 36 | B39: Master Nmap | C39: =B39 & " #" &A39 -> Master Nmap #36 | E39: =COUNTIF('Scenses 🎬'!C:C,C39) -> 0
A40: 37 | B40: Master Nmap | C40: =B40 & " #" &A40 -> Master Nmap #37 | E40: =COUNTIF('Scenses 🎬'!C:C,C40) -> 0
A41: 38 | B41: Master Nmap | C41: =B41 & " #" &A41 -> Master Nmap #38 | E41: =COUNTIF('Scenses 🎬'!C:C,C41) -> 0
A42: 39 | B42: Master Nmap | C42: =B42 & " #" &A42 -> Master Nmap #39 | E42: =COUNTIF('Scenses 🎬'!C:C,C42) -> 0
A43: 40 | B43: Master Nmap | C43: =B43 & " #" &A43 -> Master Nmap #40 | E43: =COUNTIF('Scenses 🎬'!C:C,C43) -> 0
A44: 1 | B44: Logic in Motion | C44: =B44 & " #" &A44 -> Logic in Motion #1 | D44: https://youtube.com/shorts/yTeFxKtx12Y?feature=share | E44: =COUNTIF('Scenses 🎬'!C:C,C44) -> 0
A45: 2 | B45: Logic in Motion | C45: =B45 & " #" &A45 -> Logic in Motion #2 | D45: https://youtube.com/shorts/AOMSNPGwqzY?feature=share | E45: =COUNTIF('Scenses 🎬'!C:C,C45) -> 0
A46: 3 | B46: Logic in Motion | C46: =B46 & " #" &A46 -> Logic in Motion #3 | D46: https://youtube.com/shorts/G3Nlj1b5v9k?feature=share | E46: =COUNTIF('Scenses 🎬'!C:C,C46) -> 0
A47: 4 | B47: Logic in Motion | C47: =B47 & " #" &A47 -> Logic in Motion #4 | D47: https://youtube.com/shorts/DgcOUrTPY74?feature=share | E47: =COUNTIF('Scenses 🎬'!C:C,C47) -> 0
A48: 5 | B48: Logic in Motion | C48: =B48 & " #" &A48 -> Logic in Motion #5 | D48: https://youtube.com/shorts/Uly1siESs34?feature=share | E48: =COUNTIF('Scenses 🎬'!C:C,C48) -> 0
A49: 6 | B49: Logic in Motion | C49: =B49 & " #" &A49 -> Logic in Motion #6 | D49: https://youtube.com/shorts/Ja2RjLxBlrk?feature=share | E49: =COUNTIF('Scenses 🎬'!C:C,C49) -> 0
A50: 7 | B50: Logic in Motion | C50: =B50 & " #" &A50 -> Logic in Motion #7 | D50: https://youtube.com/shorts/dPmOtIB1BBw?feature=share | E50: =COUNTIF('Scenses 🎬'!C:C,C50) -> 0
A51: 8 | B51: Logic in Motion | C51: =B51 & " #" &A51 -> Logic in Motion #8 | D51: https://youtube.com/shorts/ZUfNkKHmhIM?feature=share | E51: =COUNTIF('Scenses 🎬'!C:C,C51) -> 0
A52: 9 | B52: Logic in Motion | C52: =B52 & " #" &A52 -> Logic in Motion #9 | D52: https://youtube.com/shorts/wF2OQQobC5s?feature=share | E52: =COUNTIF('Scenses 🎬'!C:C,C52) -> 0
A53: 10 | B53: Logic in Motion | C53: =B53 & " #" &A53 -> Logic in Motion #10 | D53: https://youtube.com/shorts/W93Zrk4xwY0?feature=share | E53: =COUNTIF('Scenses 🎬'!C:C,C53) -> 0
A54: 11 | B54: Logic in Motion | C54: =B54 & " #" &A54 -> Logic in Motion #11 | D54: https://youtube.com/shorts/YFSXgrE22HU?feature=share | E54: =COUNTIF('Scenses 🎬'!C:C,C54) -> 0
A55: 12 | B55: Logic in Motion | C55: =B55 & " #" &A55 -> Logic in Motion #12 | D55: https://youtube.com/shorts/kpSNhqOnyaw?feature=share | E55: =COUNTIF('Scenses 🎬'!C:C,C55) -> 0
... A59: 16 | B59: Logic in Motion | C59: =B59 & " #" &A59 -> Logic in Motion #16 | D59: https://youtube.com/shorts/wCI0iL3jXBM?feature=share | E59: =COUNTIF('Scenses 🎬'!C:C,C59) -> 0
A60: 17 | B60: Logic in Motion | C60: =B60 & " #" &A60 -> Logic in Motion #17 | E60: =COUNTIF('Scenses 🎬'!C:C,C60) -> 0
...

Sheet Scenses 🎬
B2: Senario Lookup
A5: ROW | B5: ID | C5: Episode | D5: SCN Count | E5: SCN Number | F5: Scense Title | G5: SCN Hook | H5: SCN Senario | I5: SCN Body
A6: 1 | B6: ="SCN" & A6 -> SCN1 | C6: NETCAT Mastery — From Zero to Security Researcher #19 | D6: =COUNTIF(C:C,C6) -> 4 | E6: 1 | F6: Showing Content Hook | G6: Send A Raw UDP Datagrams To A Target Host | H6: Hook On Top, YouTube Logo & Scense Body Bellow Each Other | I6: Netcat Mastery Episode 18, Https://YouTube.com/@Unique_Sources
A7: =A6+1 -> 2 | B7: ="SCN" & A7 -> SCN2 | C7: NETCAT Mastery — From Zero to Security Researcher #19 | D7: =COUNTIF(C:C,C7) -> 4 | E7: 2 | F7: Execute Command On Terminal | G7: Kali Terminal Shell | H7: Open a terminal and show users how can send a raw UDP Datagrams To a target host | I7: None
A8: =A7+1 -> 3 | B8: ="SCN" & A8 -> SCN3 | C8: NETCAT Mastery — From Zero to Security Researcher #19 | D8: =COUNTIF(C:C,C8) -> 4 | E8: 3 | F8: Show Fast Tip | G8: Fast And Technical(TIP) | H8: Open a tip about this episode | I8: Fast & Techninal Tip \n UDP SEND \n nc -u <HOST> <PORT> \n -u Switch case will sends UDP DIAGRAM to a peer
A9: =A8+1 -> 4 | B9: ="SCN" & A9 -> SCN4 | C9: NETCAT Mastery — From Zero to Security Researcher #19 | D9: =COUNTIF(C:C,C9) -> 4 | E9: 4 | F9: Next Episode(SEASON 1 LAST EPISODE): Fast reView 1-20 | G9: Fast Revisit All 1-20 netcat flags | H9: Show Next Comming Episode | I9: Fast reView All 1-20 Flags -h -l -v -n -w -u -z -k -p -6 -N.
A10: =A9+1 -> 5 | B10: ="SCN" & A10 -> SCN5 | C10: Master Nmap Recon: Zero to Security Researcher#29 | D10: =COUNTIF(C:C,C10) -> 1 | E10: 1 | F10: Find Vulnerabillty In Real World Like A Hackers | Nmap NSE Default Script #29 | G10: You want to scan and find a VULNERABILLTY to Exp;oit them? | H10: Showing NMAP Logo Top OF SCREEN & Collection Name wih YouTube logo | I10: Master Nmap Episode 29, HTTPS://YouTube.com/Unique Sources
A11: =A10+1 -> 6 | B11: ="SCN" & A11 -> SCN6 | C11: Master Nmap #DEMO | D11: =COUNTIF(C:C,C11) -> 1
B12: COUNT | C12: =COUNTA(Scenses[Episode]) -> 6

Sheet Languages 🌍
A1: ID | B1: Name
A2: 1 | B2: English
A3: 2 | B3: English(USA)
A4: 3 | B4: ENGLISH(UK)
A5: 4 | B5: Russian
A6: 5 | B6: Polish
A7: 6 | B7: Persian
A8: 7 | B8: Jepanies
A9: 8 | B9: German
A10: 9 | B10: French
A11: 10 | B11: Arabic

Sheet Assets👁️👁️
A1: ROW | B1: Assets ID | C1: Type | D1: Name | E1: Context | F1: Description | G1: Storage Location
A2: 1 | B2: ="AST" & A2 -> AST1 | C2: Emojie | D2: • | E2: • | F2: • | G2: None
A3: =A2 + 1 -> 2 | B3: ="AST" & A3 -> AST2 | C3: Emojie | D3: 💻 | E3: 💻 | F3: 💻 | G3: None
B4: ="AST" & A4 -> AST | C4: Emojie | D4: 📌 | E4: 📌 | F4: 📌 | G4: None
B5: ="AST" & A5 -> AST | C5: Emojie | D5: 👇 | E5: 👇 | F5: 👇 | G5: None
B6: ="AST" & A6 -> AST | C6: Emojie | D6: 👁️ | E6: 👁️ | F6: 👁️ | G6: None
B7: ="AST" & A7 -> AST | C7: Emojie | D7: ♥️ | E7: ♥️ | F7: ♥️ | G7: None
B8: ="AST" & A8 -> AST | C8: Emojie | D8: 🎬 | E8: 🎬 | F8: 🎬 | G8: None
B9: ="AST" & A8 -> AST | C9: Emojie | D9: 🔔 | E9: 🔔 | F9: 🔔 | G9: None
B10: ="AST" & A9 -> AST | C10: Emojie | D10: 🔍 | E10: 🔍 | F10: 🔍 | G10: None
B11: ="AST" & A10 -> AST | C11: Emojie | D11: ⚠️ | E11: ⚠️ | F11: ⚠️ | G11: None
B12: ="AST" & A11 -> AST | C12: Emojie | D12: 🗨️ | E12: 🗨️ | F12: 🗨️ | G12: None
B13: ="AST" & A12 -> AST | C13: Emojie | D13: ⏭️ | E13: ⏭️ | F13: ⏭️ | G13: None
B14: ="AST" & A13 -> AST | C14: Emojie | D14: ⏮️ | E14: ⏮️ | F14: ⏮️
B15: ="AST" & A13 -> AST | C15: Emojie | D15: 📐 | E15: 📐 | F15: 📐 | G15: None
B16: ="AST" & A14 -> AST | C16: Emojie | D16: 🔗 | E16: 🔗 | F16: 🔗 | G16: None
B17: ="AST" & A15 -> AST | E17: 🖊️
B18: ="AST" & A16 -> AST | D18: 🫙 | E18: 📃
B19: ="AST" & A17 -> AST | E19: 🌍
B20: ="AST" & A18 -> AST | E20: 🎉
B21: ="AST" & A19 -> AST | E21: ⌛ | F21: ⚙️
B22: ="AST" & A20 -> AST | E22: 🐞
B23: ="AST" & A21 -> AST | E23: 🧊
B24: ="AST" & A22 -> AST | E24: 🧠
B25: ="AST" & A23 -> AST | E25: 🔑

Sheet Subtitles 🔍
A1: Episode | B1: Language | C1: Time duration | D1: Text
A2: Master Nmap #15

Sheet Collections 📃
A1: ID | B1: name | C1: Title | D1: Description | E1: type | F1: Share Link
A2: COLL1 | B2: Master Nmap | C2: Master Nmap Recon | Zero to Security Researcher | D2: One Command per Short ! Learn network scanning and recon from the ground up-one switch at a time. Designed for Kali Linux users and cybersecurity learners; This series delivers fast, terminal-first Shorts that cut straight to practical implementation. What You’ll Learn: 1. Host Discovery (-sn) Locate live targets without port noise 2. SYN Stealth Scan (-sS) - The standard reconnaissance baseline 3. TCP Connect (-sT) - Reliable scanning when raw sockets aren't an option 4. Service Versioning (-sV) - Fingerprint running applications and services 5. Default Scripts (-sC) - Run safe, practical NSE scripts instantly 6. OS Fingerprinting (-O) - Identify target operating systems 7. Aggressive Scan (-A) - Combine OS, version detection, scripts, and traceroute 8. Timing Templates (-T0 to -T4) - Balance speed against network stealth 9. Output Formats (-oN / -oX) - Export clean scan results for reporting 10. UDP Scanning (-sU) - Map hidden services and UDP ports 11. NSE Scripts (--script) - Target specific vulnerability checks 12. Target Exclusion (--exclude) - Filter out sensitive or out-of-scope hosts Format & Style: One focused command per episode with real-time terminal output Clear breakdowns: Command, syntax breakdown, and practical tips No fluff: Terminal-first, practical security workflows Mission: Step by step until becoming a security researcher. ⚠️ Ethical Disclaimer: Only scan systems you own or have explicit authorization to test. Unauthorized scanning is strictly prohibited. Authorized Practice Targets: scanme.nmap.org | 127.0.0.1 📌 Resources & Links: Official Documentation: https://nmap.org/book/man.html Practice Host: https://scanme.nmap.org/ 🔔 Subscribe to Unique Sources for more hands-on security tooling, recon walkthroughs, and Linux tutorials. #Nmap #CyberSecurity #KaliLinux #EthicalHacking #InfoSec #PenetrationTesting #NetworkScanning #YouTubeShorts | E2: course | F2: =HYPERLINK("https://www.youtube.com/playlist?list=PLZJ5LX101rX0") -> https://www.youtube.com/playlist?list=PLZJ5LX101rX0
A3: COLL2 | B3: NETCAT Mastery | C3: NETCAT Mastery — From Zero to Security Researcher | D3: Learn netcat the right way — one flag at a time. This collection walks you from your first connect to listen mode, file transfer, UDP, banners, and clean lab habits — in bite-sized vertical Shorts built for Kali-style terminal learning. What you'll master: • Install check (nc -h) — confirm the tool before you connect • TCP connect — talk to a local service on a port • Verbose (-v) — see succeed / fail clearly • Listen (-l / -lv) — the other side of every lab • No DNS (-n) and timeout (-w) — cleaner, safer labs • Chat & file transfer — pipe and redirect over TCP • UDP (-u) — datagram listen and send • Zero-I/O (-z) — fast port probes • Keep-open (-k), source port (-p), IPv6 (-6), EOF (-N) • HTTP banner grabs — talk protocols by hand Every episode: → One real command typed in a glass terminal → Realistic netcat output at human pace → One galactic explanation card — headline, command, tip → Next episode tease at the end Series vibe: calm authority. Dark ops room. No fluff. Terminal-first. Tagline: Step by step until becoming a security researcher. ⚠️ Lab ethics: only connect to targets you own or have explicit permission to test. Practice targets: 127.0.0.1 · localhost · ::1 This series teaches networking with netcat — not reverse shells. New Shorts drop in order — start at ep.01 and binge the path. If a clip helped you, share it with someone learning networking tools. Subscribe @Unique_Sources for netcat mastery + more security tooling series. #Netcat #CyberSecurity #KaliLinux #EthicalHacking #InfoSec #Networking #YouTubeShorts #SecurityResearcher #Linux #TechEducation #CommandLine #Homelab #LearnHacking #TCP #UDP | E3: Play List | F3: =HYPERLINK("https://www.youtube.com/playlist?list=PLQETPy4tSsME") -> https://www.youtube.com/playlist?list=PLQETPy4tSsME
A4: COLL3 | B4: Logic in Motion | C4: Logic in Motion | D4: Logic in Motion turns MATH into living ART, One algorithm per Short. Pure generative art synced to ambient sound. Code snippets are included in each description. Created using Python & JavaScript. 👁️ What you'll see: • EP1. How a Rolling Circle Draws Infinite Geometry | Logic in Motion #01 • EP2. Watch Angles Weave a Star | Logic in Motion #02 • EP3. The Secret Equation Behind a Seashell | Logic in Motion #03 • EP4. How One Cosine Draws a Rose | Logic in Motion #04 • EP5. The Koch Snowflake Algorithm | Logic in Motion #05 • EP6. The Illusion of Motion | Parallel Lines and Curves | Logic in Motion #06 • EP7. Classic Spirograph Geometry with #Python Turtle | Logic in Motion #07 • EP8. This Shape Comes From Just ONE Equation | Logic in Motion #08 • EP9. How a Circle Rolls Into a Heart | Logic in Motion #09 • EP10. How Code Draws a 3D Torus Knot #10 • EP11. How 3 Lines of Math Draw Endless Chaos | Logic in Motion #11 • EP12. Why This Boundary Never Ends | Logic in Motion #12 • EP13. The Julia Set • EP14. The • EPitrochoid Lattice • EP15. The N• EPhroid Web • EP16. The Deltoid Star • EP17. The Lemniscate of Bernoulli • EP18. The Archimedean Spiral • EP19. The Hyperbolic Spiral • EP20. The Ceva & Pascal Conics • EP21. The Aizawa Attractor • EP22. The Clifford Torus Attractor • EP23. The De Jong Attractor • EP24. The Thomas Cyclical Attractor • EP25. The Halley Fractal • EP26. The Newton Fractal • EP27. The Apollonian Gasket • EP28. The Penrose Tiling • EP29. The Navier-Stokes Vortex • EP30. The Grand Unified Quantum Lattice • EP31. The Bloch Sphere • EP32. The Schrödinger Wav• EPacket • EP33. Quantum Entanglement Matrix • EP34. The Quantum Harmonic Oscillator • EP35. Quantum Tunneling Potential Well • EP36. The Sacred Metatron’s Cube • EP37. The Flower of Life • EP38. The Sri Yantra • EP39. The Penrose Quasicrystal Lattice • EP40. The Hyperdimensional Hypersphere • EP41. The Zero-Point Vacuum • EP42. The Entropy Equilibrium • EP43. The Null Geodesic • EP44. The Silent Monopole • EP45. The Event Horizon • EP46. The Vacuum Fluctuation • EP47. The Zen Master Equation • EP48. The CMB Whisper • EP49. The Tao of Zero • EP50. The Grand Silence • EP51. The Calabi-Yau Manifold • EP52. The Poincaré Disk • EP53. The Ryu-Takayanagi Surface • EP54. The Hopf Fibration • EP55. The Quantum Foam • EP56. The Penrose Diagram • EP57. The Klein Bottle • EP58. The Borromean Rings • EP59. The Mandelbulb Fractal • EP60. The Omniverse Nexus 🔔 Enjoying the visuals? Subscribe & Share this Short with anyone who appreciates math. @Unique_Sources 📌 Full Series Playlist: https://youtube.com/playlist?list=PLMG4RCtlrh18&si=jl8Cz_FDYUVfpHno #LogicInMotion #GenerativeArt #MathArt #CreativeCoding #AlgorithmicArt #Fractals #DigitalArt #YouTubeShorts #Shorts | E4: Play List | F4: =HYPERLINK("https://www.youtube.com/playlist?list=PLMG4RCtlrh18") -> https://www.youtube.com/playlist?list=PLMG4RCtlrh18

Sheet Body Content
A1: Hook Description | B1: Description | C1: Tags | D1: Related Video | E1: Subtitle | F1: Quiz | G1: Scenses Count | H1: Pinned Comment
A2: Visualizing mathematical beauty through code. In this episode of Logic in Motion, we explore The Mandelbrot Fractal, infinite complex boundaries, using the Mandelbrot set. | B2: 📐 The Math & Logic: • Concept: Complex quadratic iteration • Key Formula / Rule: z → z² + c, colored by escape time • Tools: JavaScript / Canvas 🔁 Logic in Motion Series: • Watch the full playlist: https://youtube.com/playlist?list=PLMG4RCtlrh18&si=jl8Cz_FDYUVfpHno • Previous Episode: How 3 Lines of Math Draw Endless Chaos | Logic in Motion #11 • Next Episode: What If the Constant Never Changes | Logic in Motion #13 💻 Source Code & Resources: • Code repository / Gist: https://github.com/irAbs174/Logic_in_motion #LogicInMotion #CreativeCoding #Python #GenerativeArt #MathArt #Short | C2: 404 | E2: FALSE | F2: FALSE | G2: =Countif(Scenses[Episode],#REF!) -> 0 | H2: 404
A3: In This Video We Are Showing How Can Send A Raw UDP Datagrams To A Target Host On Spec Port Using Netcat(nc -u) Switch Case. | B3: 💻 Command: nc -u 127.0.0.1 9999 📌 Tip: Make sure you pair this with an active UDP listener on the receiving side(e.g., nc -u -l 9999). Subscribe to Unique Sources for quick Linux, networking & cybersecurity tips! #Netcat #Networking #LinuxTips #CyberSecurity #Shorts | C3: netcat, nc command, udp testing, send udp datagram netcat, netcat udp, linux networking, cybersecurity basics, nc -u, network engineering, linux terminal, sysadmin tips | E3: TRUE | F3: FALSE | G3: =Countif(Scenses[Episode],#REF!) -> 0 | H3: 💻 Quick Cheat Sheet: • Send UDP: nc -u 127.0.0.1 9999 • Listen(UDP): nc -u -l 9999 📌 Note: Always ensure your firewall or target port allows UDP traffic when testing! What networking or Linux tool do you want a quick breakdown of next? Let me know below! 👇
A4: -sC runs nmap's DEFAULT NSE script set | One Flag, Instant Recon. | B4: -sC runs nmap's DEFAULT NSE script set | One Flag, Instant Recon. Command: $ nmap -sC -p 22 127.0.0.1 What it does: Loads safe default scripts automatically Grabs banners, versions, service info Zero extra setup Check Pined Commend for PRO TIP. Next Episode: -O for OS detection. #Nmap #NSE #CyberSecurity #EthicalHacking #KaliLinux #Shorts #InfoSec #Recon | C4: nmap, nmap -sC, nmap tutorial, NSE scripts, nmap default scripts, ethical hacking, cybersecurity shorts, kali linux, recon, port scanning, nmap flags, infosec, penetration testing, hacking tools, nmap commands | E4: TRUE | F4: FALSE | G4: =Countif(Scenses[Episode],#REF!) -> 0 | H4: Pro tip: -sC = --script=default. Same things with less typing.
A5: 404 | B5: Episode 13: Julia Set let zx = zx * zx - zy * zy + cr; let zy = 2 * zx_old * zy + ci; | C5: 404 | D5: Why This Boundary Never Ends | Logic in Motion #12 | E5: FALSE | F5: FALSE | G5: =Countif(Scenses[Episode],#REF!) -> 0 | H5: 404
A6: 404 | B6: nc -u host port sends UDP datagrams to a peer. Command: nc -u 127.0.0.1 9999 Tip: Pair with a UDP listener on the other side. NEXT → Flag Cheat Sheet · nc -h ⚠️ Lab only: 127.0.0.1 / localhost / ::1 #Netcat #CyberSecurity #KaliLinux #EthicalHacking #InfoSec #YouTubeShorts | C6: 404 | E6: FALSE | F6: FALSE | G6: =Countif(Scenses[Episode],#REF!) -> 0 | H6: 404
A7: 404 | B7: Guess the operating system? $ nmap -O 127.0.0.1 TCP/IP fingerprinting treat as a lead. Save for enum notes. . . . #Nmap #CyberSecurity #EthicalHacking #KaliLinux #InfoSec #TechReels #LearnOnInstagram #TechTips #SecurityResearcher #Recon #Homelab #PenetrationTesting | C7: 404 | E7: FALSE | F7: FALSE | G7: =Countif(Scenses[Episode],#REF!) -> 0 | H7: 404
A8: 404 | B8: // 14 | C8: 404 | D8: The Julia Set #13 | E8: FALSE | F8: FALSE | G8: =Countif(Scenses[Episode],#REF!) -> 0 | H8: 404
A9: 404 | B9: Revisit -h | -l -v -n -w -u -z -k -p -6 -N. Command: nc -h Tip: Save the flag set then practice on localhost. NEXT → Beginner Atlas · netcat flag flash cards ⚠️ Lab only: 127.0.0.1 / localhost / ::1 #Netcat #CyberSecurity #KaliLinux #EthicalHacking #InfoSec #YouTubeShorts | C9: 404 | E9: FALSE | F9: FALSE | G9: =Countif(Scenses[Episode],#REF!) -> 0 | H9: 404
A10: 404 | B10: -A bundles version, scripts, OS detect & traceroute. $ nmap -A -p 22 127.0.0.1 Next: UDP Scan(-sU). #Nmap #CyberSecurity #KaliLinux #EthicalHacking #InfoSec #YouTubeShorts | C10: 404 | E10: FALSE | F10: FALSE | G10: =Countif(Scenses[Episode],#REF!) -> 0 | H10: 404
A11: 404 | B11: //15 | C11: 404 | D11: The Epitrochoid Lattice #14 | E11: FALSE | F11: FALSE | G11: =Countif(Scenses[Episode],#REF!) -> 0 | H11: 404
A12: 404 | B12: nc Extra Verbose(-vv)| Ep.21 DESCRIPTION: -vv doubles verbosity more connect diagnostics. Command: nc -vv 127.0.0.1 22 Tip: Stack -v when one level is not enough detail. NEXT → Line Interval(-i) nc -i 1 127.0.0.1 9999 ⚠️ Lab only: 127.0.0.1 / localhost / ::1 #Netcat #CyberSecurity #KaliLinux #EthicalHacking #InfoSec #YouTubeShorts | C12: 404 | E12: FALSE | F12: FALSE | G12: =Countif(Scenses[Episode],#REF!) -> 0 | H12: 404
A13: 404 | B13: -sU probes UDP. Results are slower & often ambiguous. $ nmap -sU -p 53 127.0.0.1 Next: ACK Scan(-sA). #Nmap #CyberSecurity #KaliLinux #EthicalHacking #InfoSec #YouTubeShorts | C13: 404 | E13: FALSE | F13: FALSE | G13: =Countif(Scenses[Episode],#REF!) -> 0 | H13: 404
A14: 404 | B14: //16 | C14: 404 | D14: The Nephroid Web #15 | E14: FALSE | F14: FALSE | G14: =Countif(Scenses[Episode],#REF!) -> 0 | H14: 404
A15: 404 | B15: -i delays seconds between lines sent or ports probed. Command: nc -i 1 127.0.0.1 9999 Tip: Slow the pace when labs need readable timing. NEXT → Quit After EOF(-q) nc -q 1 127.0.0.1 9999 ⚠️ Lab only: 127.0.0.1 / localhost / ::1 #Netcat #CyberSecurity #KaliLinux #EthicalHacking #InfoSec #YouTubeShorts | C15: 404 | E15: FALSE | F15: FALSE | G15: =Countif(Scenses[Episode],#REF!) -> 0 | H15: 404
